Workbook

Sheet Dados
A1: AVISO | B1: =IF(COUNTIF('Interessados em analise'!B2:B18,B3)=0,"✅",COUNTIF('Interessados em analise'!B2:B18,B3)&"❌") -> ✅ | C1: =IF(COUNTIF('Interessados em analise'!B2:B18,C3)=0,"✅",COUNTIF('Interessados em analise'!B2:B18,C3)&"❌") -> ✅ | D1: =IF(COUNTIF('Interessados em analise'!B2:B18,D3)=0,"✅",COUNTIF('Interessados em analise'!B2:B18,D3)&"❌") -> ✅ | E1: =IF(COUNTIF('Interessados em analise'!B2:B18,E3)=0,"✅",COUNTIF('Interessados em analise'!B2:B18,E3)&"❌") -> ✅ | F1: =IF(COUNTIF('Interessados em analise'!B2:B18,F3)=0,"✅",COUNTIF('Interessados em analise'!B2:B18,F3)&"❌") -> ✅ | G1: =IF(COUNTIF('Interessados em analise'!B2:B18,G3)=0,"✅",COUNTIF('Interessados em analise'!B2:B18,G3)&"❌") -> ✅ | H1: =IF(COUNTIF('Interessados em analise'!B2:B18,H3)=0,"✅",COUNTIF('Interessados em analise'!B2:B18,H3)&"❌") -> ✅ | I1: =IF(COUNTIF('Interessados em analise'!B2:B18,I3)=0,"✅",COUNTIF('Interessados em analise'!B2:B18,I3)&"❌") -> ✅ | J1: =IF(COUNTIF('Interessados em analise'!B2:B18,J3)=0,"✅",COUNTIF('Interessados em analise'!B2:B18,J3)&"❌") -> ✅ | K1: =IF(COUNTIF('Interessados em analise'!B2:B18,K3)=0,"✅",COUNTIF('Interessados em analise'!B2:B18,K3)&"❌") -> ✅ | L1: =IF(COUNTIF('Interessados em analise'!B2:B18,L3)=0,"✅",COUNTIF('Interessados em analise'!B2:B18,L3)&"❌") -> ✅ | M1: =IF(COUNTIF('Interessados em analise'!B2:B18,M3)=0,"✅",COUNTIF('Interessados em analise'!B2:B18,M3)&"❌") -> ✅ | N1: =IF(COUNTIF('Interessados em analise'!B2:B18,N3)=0,"✅",COUNTIF('Interessados em analise'!B2:B18,N3)&"❌") -> ✅ | O1: =IF(COUNTIF('Interessados em analise'!B2:B18,O3)=0,"✅",COUNTIF('Interessados em analise'!B2:B18,O3)&"❌") -> ✅ | P1: =IF(COUNTIF('Interessados em analise'!B2:B18,P3)=0,"✅",COUNTIF('Interessados em analise'!B2:B18,P3)&"❌") -> ✅ | Q1: =IF(COUNTIF('Interessados em analise'!B2:B18,Q3)=0,"✅",COUNTIF('Interessados em analise'!B2:B18,Q3)&"❌") -> ✅ | R1: =IF(COUNTIF('Interessados em analise'!B2:B18,R3)=0,"✅",COUNTIF('Interessados em analise'!B2:B18,R3)&"❌") -> ✅ | S1: =IF(COUNTIF('Interessados em analise'!B2:B18,S3)=0,"✅",COUNTIF('Interessados em analise'!B2:B18,S3)&"❌") -> ✅ | T1: =IF(COUNTIF('Interessados em analise'!B2:B18,T3)=0,"✅",COUNTIF('Interessados em analise'!B2:B18,T3)&"❌") -> ✅ | U1: =IF(COUNTIF('Interessados em analise'!B2:B18,U3)=0,"✅",COUNTIF('Interessados em analise'!B2:B18,U3)&"❌") -> ✅ | V1: =IF(COUNTIF('Interessados em analise'!B2:B18,V3)=0,"✅",COUNTIF('Interessados em analise'!B2:B18,V3)&"❌") -> ✅ | W1: =IF(COUNTIF('Interessados em analise'!B2:B18,W3)=0,"✅",COUNTIF('Interessados em analise'!B2:B18,W3)&"❌") -> ✅ | X1: =IF(COUNTIF('Interessados em analise'!B2:B18,X3)=0,"✅",COUNTIF('Interessados em analise'!B2:B18,X3)&"❌") -> ✅ | Y1: =IF(COUNTIF('Interessados em analise'!B2:B18,Y3)=0,"✅",COUNTIF('Interessados em analise'!B2:B18,Y3)&"❌") -> ✅ | Z1: =IF(COUNTIF('Interessados em analise'!B2:B18,Z3)=0,"✅",COUNTIF('Interessados em analise'!B2:B18,Z3)&"❌") -> ✅ | AA1: =IF(COUNTIF('Interessados em analise'!B2:B18,AA3)=0,"✅",COUNTIF('Interessados em analise'!B2:B18,AA3)&"❌") -> ✅ | AB1: =IF(COUNTIF('Interessados em analise'!B2:B18,AB3)=0,"✅",COUNTIF('Interessados em analise'!B2:B18,AB3)&"❌") -> ✅ | AC1: =IF(COUNTIF('Interessados em analise'!B2:B18,AC3)=0,"✅",COUNTIF('Interessados em analise'!B2:B18,AC3)&"❌") -> ✅ | AD1: =IF(COUNTIF('Interessados em analise'!B2:B18,AD3)=0,"✅",COUNTIF('Interessados em analise'!B2:B18,AD3)&"❌") -> ✅ | AE1: =IF(COUNTIF('Interessados em analise'!B2:B18,AE3)=0,"✅",COUNTIF('Interessados em analise'!B2:B18,AE3)&"❌") -> ✅ | AF1: =IF(COUNTIF('Interessados em analise'!B2:B18,AF3)=0,"✅",COUNTIF('Interessados em analise'!B2:B18,AF3)&"❌") -> ✅ | AG1: =IF(COUNTIF('Interessados em analise'!B2:$B1000,AG3)=0,"✅",COUNTIF('Interessados em analise'!B2:$B1000,AG3)&"❌") -> ✅ | AH1: =IF(COUNTIF('Interessados em analise'!B2:$B1000,AH3)=0,"✅",COUNTIF('Interessados em analise'!B2:$B1000,AH3)&"❌") -> ✅ | AI1: =IF(COUNTIF('Interessados em analise'!B2:$B1000,AI3)=0,"✅",COUNTIF('Interessados em analise'!B2:$B1000,AI3)&"❌") -> ✅ | AJ1: =IF(COUNTIF('Interessados em analise'!$B2:$B1000,AJ3)=0,"✅",COUNTIF('Interessados em analise'!$B2:$B1000,AJ3)&"❌") -> ✅ | AK1: =IF(COUNTIF('Interessados em analise'!$B2:$B1000,AK3)=0,"✅",COUNTIF('Interessados em analise'!$B2:$B1000,AK3)&"❌") -> ✅ | AL1: =IF(COUNTIF('Interessados em analise'!$B2:$B1000,AL3)=0,"✅",COUNTIF('Interessados em analise'!$B2:$B1000,AL3)&"❌") -> ✅
A3: Dias | B3: 46196 | C3: 46197 | D3: 46198 | E3: 46199 | F3: 46200 | G3: 46201 | H3: 46202 | I3: 46203 | J3: 46204 | K3: 46205 | L3: 46206 | M3: 46207 | N3: 46208 | O3: 46209 | P3: 46210 | Q3: 46211 | R3: 46212 | S3: 46213 | T3: 46214 | U3: 46215 | V3: 46216 | W3: 46217 | X3: 46218 | Y3: 46219 | Z3: 46220 | AA3: 46221 | AB3: 46222 | AC3: 46223 | AD3: 46224 | AE3: 46225 | AF3: 46226 | AG3: 46227 | AH3: 46228 | AI3: 46229 | AJ3: 46230 | AK3: 46231 | AL3: 46232
A5: Quantidade Por dias | B5: =SUM(B8:B10,B12,B15:B21) -> 21 | C5: =SUM(C8:C10,C12,C15:C21) -> 7 | D5: =SUM(D8:D10,D12,D15:D21) -> 10 | E5: =SUM(E8:E10,E12,E15:E21) -> 10 | F5: =SUM(F8:F10,F12,F15:F21) -> 6 | G5: =SUM(G8:G10,G12,G15:G21) -> 7 | H5: =SUM(H8:H10,H12,H15:H21) -> 10 | I5: =SUM(I8:I10,I12,I15:I21) -> 19 | ... AL5: =SUM(AL8:AL10,AL12,AL15:AL21) -> 12
A7: interessados | B7: # | C7: # | D7: # | E7: # | F7: # | G7: # | H7: # | I7: # | J7: # | K7: # | L7: # | M7: # | N7: # | O7: # | P7: # | Q7: # | R7: # | S7: # | T7: # | U7: # | V7: # | W7: # | X7: # | Y7: # | Z7: # | AA7: # | AB7: # | AC7: # | AD7: # | AE7: # | AF7: # | AG7: # | AH7: # | AI7: # | AJ7: # | AK7: # | AL7: #
A8: Comprou | M8: 1 | P8: 1
A9: Interessado mas sem resposta | B9: 2 | D9: 1 | G9: 2 | I9: 3 | J9: 1 | K9: 3 | L9: 2 | M9: 2 | N9: 1 | P9: 1 | R9: 2 | T9: 1 | V9: 4 | W9: 2 | X9: 3 | Z9: 2 | AA9: 2 | AB9: 2 | AD9: 3 | AE9: 2 | AG9: 4 | AH9: 2 | AI9: 2 | AJ9: 1 | AK9: 1 | AL9: 3
A10: Compra Futura | B10: 2 | D10: 3 | H10: 1 | M10: 1 | Q10: 1 | T10: 1 | Z10: 1 | AF10: 1 | AJ10: 1
A12: Sem Retorno | B12: 8 | C12: 5 | D12: 3 | E12: 8 | F12: 4 | G12: 2 | H12: 5 | I12: 11 | J12: 3 | K12: 5 | L12: 10 | M12: 7 | N12: 6 | O12: 12 | P12: 16 | Q12: 9 | R12: 4 | S12: 8 | T12: 6 | U12: 5 | V12: 8 | W12: 7 | X12: 4 | Y12: 4 | Z12: 4 | AA12: 3 | AB12: 6 | AC12: 5 | AD12: 3 | AE12: 4 | AF12: 6 | AG12: 7 | AH12: 7 | AI12: 7 | AJ12: 7 | AK12: 9 | AL12: 5
A14: Perdidos | B14: # | C14: # | D14: # | E14: # | F14: # | G14: # | H14: # | I14: # | J14: # | K14: # | L14: # | M14: # | N14: # | O14: # | P14: # | Q14: # | R14: # | S14: # | T14: # | U14: # | V14: # | W14: # | X14: # | Y14: # | Z14: # | AA14: # | AB14: # | AC14: # | AD14: # | AE14: # | AF14: # | AG14: # | AH14: # | AI14: # | AJ14: # | AK14: # | AL14: #
A15: Orçamento insuficiente | B15: 1 | Z15: 1
A16: O produto não se encaixa à necessidade | B16: 1 | M16: 1 | P16: 1 | X16: 1 | Y16: 1 | AD16: 1
A17: Não satisfeito com as condições | B17: 1
A18: Comprado do concorrente | X18: 1 | Y18: 1
A19: Currículo (busca de emprego) | B19: 4 | D19: 1 | E19: 2 | G19: 1 | H19: 3 | I19: 4 | J19: 1 | K19: 3 | L19: 3 | N19: 2 | O19: 3 | P19: 3 | Q19: 2 | R19: 3 | S19: 4 | V19: 2 | W19: 7 | X19: 5 | Y19: 5 | Z19: 3 | AA19: 5 | AB19: 7 | AC19: 14 | AD19: 15 | AE19: 5 | AF19: 6 | AG19: 8 | AH19: 4 | AI19: 3 | AJ19: 11 | AK19: 7 | AL19: 1
A20: Fora da região
A21: Engano | B21: 2 | C21: 2 | D21: 2 | F21: 2 | G21: 2 | H21: 1 | I21: 1 | J21: 2 | L21: 3 | M21: 1 | O21: 3 | P21: 2 | R21: 3 | S21: 2 | T21: 3 | V21: 3 | W21: 3 | X21: 6 | Y21: 1 | Z21: 2 | AA21: 3 | AB21: 4 | AC21: 1 | AE21: 5 | AG21: 3 | AH21: 5 | AI21: 4 | AJ21: 2 | AK21: 2 | AL21: 3
A22: Outros (Não contabilizado aos leads) | F22: 1 | S22: 1 | AI22: 1 | AJ22: 1 | AL22: 2
A25: Obs: O icone ❌ indica que tem um lead em analise por interesse
A26: Obs: O icone ✅ indica que todos os leads do dia estão na tabela
A28: AVISO | B28: =IF(COUNTIF('Interessados em analise'!$B$1:$B$45,B30)=0,"✅",COUNTIF('Interessados em analise'!$B$1:$B$45,B30)&"❌") -> ✅ | C28: =IF(COUNTIF('Interessados em analise'!$B$1:$B$45,C30)=0,"✅",COUNTIF('Interessados em analise'!$B$1:$B$45,C30)&"❌") -> ✅ | D28: =IF(COUNTIF('Interessados em analise'!$B$1:$B$45,D30)=0,"✅",COUNTIF('Interessados em analise'!$B$1:$B$45,D30)&"❌") -> ✅ | E28: =IF(COUNTIF('Interessados em analise'!$B$1:$B$45,E30)=0,"✅",COUNTIF('Interessados em analise'!$B$1:$B$45,E30)&"❌") -> ✅ | F28: =IF(COUNTIF('Interessados em analise'!$B$1:$B$45,F30)=0,"✅",COUNTIF('Interessados em analise'!$B$1:$B$45,F30)&"❌") -> ✅ | G28: =IF(COUNTIF('Interessados em analise'!$B$1:$B$45,G30)=0,"✅",COUNTIF('Interessados em analise'!$B$1:$B$45,G30)&"❌") -> ✅ | H28: =IF(COUNTIF('Interessados em analise'!$B$1:$B$45,H30)=0,"✅",COUNTIF('Interessados em analise'!$B$1:$B$45,H30)&"❌") -> ✅ | I28: =IF(COUNTIF('Interessados em analise'!$B$1:$B$45,I30)=0,"✅",COUNTIF('Interessados em analise'!$B$1:$B$45,I30)&"❌") -> ✅ | ... AL28: =IF(COUNTIF('Interessados em analise'!$B$1:$B$45,AL30)=0,"✅",COUNTIF('Interessados em analise'!$B$1:$B$45,AL30)&"❌") -> ✅
A30: Dias | B30: 46253 | C30: 46254 | D30: 46255 | E30: 46256 | F30: 46257 | G30: 46258 | H30: 46259 | I30: 46260 | J30: 46261 | K30: 46262 | L30: 46263 | M30: 46264 | N30: 46265 | O30: 46266 | P30: 46267 | Q30: 46268 | R30: 46269 | S30: 46270 | T30: 46271 | U30: 46272 | V30: 46273 | W30: 46274 | X30: 46275 | Y30: 46276 | Z30: 46277 | AA30: 46278 | AB30: 46279 | AC30: 46280 | AD30: 46281 | AE30: 46282 | AF30: 46283 | AG30: 46284 | AH30: 46285 | AI30: 46286 | AJ30: 46287 | AK30: 46288 | AL30: 46289
A32: Quantidade Por dias | B32: =SUM(B35:B37,B39,B42:B48) -> 26 | C32: =SUM(C35:C37,C39,C42:C48) -> 35 | D32: =SUM(D35:D37,D39,D42:D48) -> 18 | E32: =SUM(E35:E37,E39,E42:E48) -> 25 | F32: =SUM(F35:F37,F39,F42:F48) -> 28 | G32: =SUM(G35:G37,G39,G42:G48) -> 38 | H32: =SUM(H35:H37,H39,H42:H48) -> 20 | I32: =SUM(I35:I37,I39,I42:I48) -> 34 | ... AL32: =SUM(AL35:AL37,AL39,AL42:AL48) -> 11
A34: interessados | B34: # | C34: # | D34: # | E34: # | F34: # | G34: # | H34: # | I34: # | J34: # | K34: # | L34: # | M34: # | N34: # | O34: # | P34: # | Q34: # | R34: # | S34: # | T34: # | U34: # | V34: # | W34: # | X34: # | Y34: # | Z34: # | AA34: # | AB34: # | AC34: # | AD34: # | AE34: # | AF34: # | AG34: # | AH34: # | AI34: # | AJ34: # | AK34: # | AL34: #
A35: Comprou | S35: 1 | Z35: 1
A36: Interessado mas sem resposta | G36: 1 | K36: 1 | N36: 2 | T36: 1 | V36: 1 | AF36: 1 | AI36: 1
A37: Compra Futura | C37: 1 | E37: 2 | F37: 1 | G37: 1 | P37: 1 | R37: 1 | X37: 1 | AD37: 2
A39: Sem Retorno | B39: 12 | C39: 18 | D39: 9 | E39: 13 | F39: 19 | G39: 10 | H39: 9 | I39: 9 | J39: 6 | K39: 6 | L39: 8 | M39: 10 | N39: 12 | O39: 13 | P39: 7 | Q39: 8 | R39: 2 | S39: 6 | T39: 6 | U39: 8 | V39: 6 | W39: 12 | X39: 4 | Y39: 5 | Z39: 4 | AA39: 6 | AB39: 7 | AC39: 3 | AD39: 6 | AE39: 4 | AF39: 4 | AG39: 8 | AH39: 7 | AI39: 9 | AJ39: 6 | AK39: 3 | AL39: 3
A41: Perdidos | B41: # | C41: # | D41: # | E41: # | F41: # | G41: # | H41: # | I41: # | J41: # | K41: # | L41: # | M41: # | N41: # | O41: # | P41: # | Q41: # | R41: # | S41: # | T41: # | U41: # | V41: # | W41: # | X41: # | Y41: # | Z41: # | AA41: # | AB41: # | AC41: # | AD41: # | AE41: # | AF41: # | AG41: # | AH41: # | AI41: # | AJ41: # | AK41: # | AL41: #
A42: Orçamento insuficiente | B42: 1
A43: O produto não se encaixa à necessidade
A44: Não satisfeito com as condições
A45: Comprado do concorrente | Z45: 1
A46: Currículo (busca de emprego) | B46: 10 | C46: 14 | D46: 6 | E46: 5 | F46: 5 | G46: 23 | H46: 9 | I46: 24 | J46: 14 | K46: 7 | L46: 4 | M46: 9 | N46: 14 | O46: 23 | P46: 20 | Q46: 19 | R46: 14 | S46: 6 | T46: 5 | U46: 9 | V46: 15 | W46: 16 | X46: 12 | Y46: 5 | Z46: 7 | AA46: 7 | AB46: 15 | AC46: 5 | AD46: 10 | AE46: 22 | AF46: 4 | AG46: 2 | AH46: 5 | AI46: 11 | AJ46: 8 | AK46: 12 | AL46: 7
A47: Fora da região
A48: Engano | B48: 3 | C48: 2 | D48: 3 | E48: 5 | F48: 3 | G48: 3 | H48: 2 | I48: 1 | J48: 1 | L48: 3 | M48: 3 | N48: 3 | O48: 5 | P48: 6 | Q48: 4 | R48: 2 | S48: 3 | U48: 3 | V48: 7 | X48: 1 | Y48: 1 | Z48: 1 | AA48: 1 | AB48: 2 | AD48: 3 | AE48: 2 | AF48: 1 | AH48: 4 | AI48: 2 | AJ48: 2 | AL48: 1
A49: Outros (Não contabilizado aos leads) | I49: 2 | N49: 3 | Q49: 1 | R49: 2 | W49: 1 | Y49: 1 | AC49: 1
A55: AVISO | B55: =IF(COUNTIF('Interessados em analise'!$B$1:$B$45,B57)=0,"✅",COUNTIF('Interessados em analise'!$B$1:$B$45,B57)&"❌") -> ✅ | C55: =IF(COUNTIF('Interessados em analise'!$B$1:$B$45,C57)=0,"✅",COUNTIF('Interessados em analise'!$B$1:$B$45,C57)&"❌") -> ✅ | D55: =IF(COUNTIF('Interessados em analise'!$B$1:$B$45,D57)=0,"✅",COUNTIF('Interessados em analise'!$B$1:$B$45,D57)&"❌") -> ✅ | E55: =IF(COUNTIF('Interessados em analise'!$B$1:$B$45,E57)=0,"✅",COUNTIF('Interessados em analise'!$B$1:$B$45,E57)&"❌") -> ✅ | F55: =IF(COUNTIF('Interessados em analise'!$B$1:$B$45,F57)=0,"✅",COUNTIF('Interessados em analise'!$B$1:$B$45,F57)&"❌") -> 1❌ | G55: =IF(COUNTIF('Interessados em analise'!$B$1:$B$45,G57)=0,"✅",COUNTIF('Interessados em analise'!$B$1:$B$45,G57)&"❌") -> ✅ | H55: =IF(COUNTIF('Interessados em analise'!$B$1:$B$45,H57)=0,"✅",COUNTIF('Interessados em analise'!$B$1:$B$45,H57)&"❌") -> ✅ | I55: =IF(COUNTIF('Interessados em analise'!$B$1:$B$45,I57)=0,"✅",COUNTIF('Interessados em analise'!$B$1:$B$45,I57)&"❌") -> ✅ | ... AL55: =IF(COUNTIF('Interessados em analise'!$B$1:$B$45,AL57)=0,"✅",COUNTIF('Interessados em analise'!$B$1:$B$45,AL57)&"❌") -> ✅
A57: Dias | B57: 46290 | C57: 46291 | D57: 46292 | E57: 46293 | F57: 46294 | G57: 46295 | H57: 46296 | I57: 46297 | J57: 46298 | K57: 46299 | L57: 46300 | M57: 46301 | N57: 46302 | O57: 46303 | P57: 46304 | Q57: 46305 | R57: 46306 | S57: 46307 | T57: 46308 | U57: 46309 | V57: 46310 | W57: 46311 | X57: 46312 | Y57: 46313 | Z57: 46314 | AA57: 46315 | AB57: 46316 | AC57: 46317 | AD57: 46318 | AE57: 46319 | AF57: 46320 | AG57: 46321 | AH57: 46322 | AI57: 46323 | AJ57: 46324 | AK57: 46325 | AL57: 46326
A59: Quantidade Por dias | B59: =SUM(B62:B64,B66,B69:B75) -> 13 | C59: =SUM(C62:C64,C66,C69:C75) -> 6 | D59: =SUM(D62:D64,D66,D69:D75) -> 6 | E59: =SUM(E62:E64,E66,E69:E75) -> 18 | F59: =SUM(F62:F64,F66,F69:F75) -> 11 | G59: =SUM(G62:G64,G66,G69:G75) -> 6 | H59: =SUM(H62:H64,H66,H69:H75) -> 10 | I59: =SUM(I62:I64,I66,I69:I75) -> 0 | ... AL59: =SUM(AL62:AL64,AL66,AL69:AL75) -> 0
A61: interessados | B61: # | C61: # | D61: # | E61: # | F61: # | G61: # | H61: # | I61: # | J61: # | K61: # | L61: # | M61: # | N61: # | O61: # | P61: # | Q61: # | R61: # | S61: # | T61: # | U61: # | V61: # | W61: # | X61: # | Y61: # | Z61: # | AA61: # | AB61: # | AC61: # | AD61: # | AE61: # | AF61: # | AG61: # | AH61: # | AI61: # | AJ61: # | AK61: # | AL61: #
...

Sheet Dashboard
A1: Total Interessados | B1: =SUM(Dados!B9:10) -> 66
A2: Total Comprou | B2: =SUM(Dados!B8:8) -> 2
A3: Total Perdidos | B3: =SUM(Dados!B15:22) -> 242
A4: Total Sem Retorno | B4: =SUM(Dados!B12:12) -> 233
A5: Interessados em analise | B5: =COUNTA('Interessados em analise'!A2:A18) -> 2
A6: Total Geral | B6: =SUM(B1:B5) -> 545
A7: Taxa de Interesse | B7: =DIVIDE(B1+B2,B6) -> 0.12477064

Sheet Interessados em analise
A1: Interessados em analise | B1: Data | C1: Descrição
A2: =5511942192114 -> 5511942192114 | B2: 46276
A3: =5519990093000 -> 5519990093000 | B3: 46294
